{
  "nbformat": 4,
  "nbformat_minor": 0,
  "metadata": {
    "colab": {
      "provenance": [],
      "toc_visible": true,
      "authorship_tag": "ABX9TyPsWdWuFhALb2fDgazoxzqO",
      "include_colab_link": true
    },
    "kernelspec": {
      "name": "python3",
      "display_name": "Python 3"
    },
    "language_info": {
      "name": "python"
    }
  },
  "cells": [
    {
      "cell_type": "markdown",
      "metadata": {
        "id": "view-in-github",
        "colab_type": "text"
      },
      "source": [
        "<a href=\"https://colab.research.google.com/github/LittelEvil/ISM6562/blob/main/ISM6562_Cassandra.ipynb\" target=\"_parent\"><img src=\"https://colab.research.google.com/assets/colab-badge.svg\" alt=\"Open In Colab\"/></a>"
      ]
    },
    {
      "cell_type": "code",
      "execution_count": 1,
      "metadata": {
        "colab": {
          "base_uri": "https://localhost:8080/"
        },
        "id": "xIn9FA0wSh0e",
        "outputId": "7179392f-a542-4604-aa5a-c6238ef19b54"
      },
      "outputs": [
        {
          "output_type": "stream",
          "name": "stdout",
          "text": [
            "Collecting cassandra-driver\n",
            "  Downloading cassandra_driver-3.29.0-cp310-cp310-manylinux_2_17_x86_64.manylinux2014_x86_64.whl (18.8 MB)\n",
            "\u001b[2K     \u001b[90m━━━━━━━━━━━━━━━━━━━━━━━━━━━━━━━━━━━━━━━━\u001b[0m \u001b[32m18.8/18.8 MB\u001b[0m \u001b[31m35.6 MB/s\u001b[0m eta \u001b[36m0:00:00\u001b[0m\n",
            "\u001b[?25hCollecting geomet<0.3,>=0.1 (from cassandra-driver)\n",
            "  Downloading geomet-0.2.1.post1-py3-none-any.whl (18 kB)\n",
            "Requirement already satisfied: click in /usr/local/lib/python3.10/dist-packages (from geomet<0.3,>=0.1->cassandra-driver) (8.1.7)\n",
            "Requirement already satisfied: six in /usr/local/lib/python3.10/dist-packages (from geomet<0.3,>=0.1->cassandra-driver) (1.16.0)\n",
            "Installing collected packages: geomet, cassandra-driver\n",
            "Successfully installed cassandra-driver-3.29.0 geomet-0.2.1.post1\n"
          ]
        }
      ],
      "source": [
        "pip install --upgrade cassandra-driver"
      ]
    },
    {
      "cell_type": "code",
      "source": [
        "import cassandra"
      ],
      "metadata": {
        "id": "Ex20sJTBS5AB"
      },
      "execution_count": 3,
      "outputs": []
    },
    {
      "cell_type": "code",
      "source": [
        "from cassandra.cluster import Cluster"
      ],
      "metadata": {
        "id": "0RaNmXOATIej"
      },
      "execution_count": 5,
      "outputs": []
    },
    {
      "cell_type": "code",
      "source": [
        "cluster = Cluster(protocol_version = 3)\n",
        "session = cluster.connect('killrvideo')"
      ],
      "metadata": {
        "colab": {
          "base_uri": "https://localhost:8080/",
          "height": 545
        },
        "id": "FYb74CppT72n",
        "outputId": "a88db712-25c5-4d21-d7c0-d0d191288ae1"
      },
      "execution_count": 6,
      "outputs": [
        {
          "output_type": "stream",
          "name": "stderr",
          "text": [
            "WARNING:cassandra.cluster:[control connection] Error connecting to 127.0.0.1:9042:\n",
            "Traceback (most recent call last):\n",
            "  File \"cassandra/cluster.py\", line 3577, in cassandra.cluster.ControlConnection._reconnect_internal\n",
            "  File \"cassandra/cluster.py\", line 3599, in cassandra.cluster.ControlConnection._try_connect\n",
            "  File \"cassandra/cluster.py\", line 1670, in cassandra.cluster.Cluster.connection_factory\n",
            "  File \"cassandra/connection.py\", line 846, in cassandra.connection.Connection.factory\n",
            "  File \"/usr/local/lib/python3.10/dist-packages/cassandra/io/asyncorereactor.py\", line 354, in __init__\n",
            "    self._connect_socket()\n",
            "  File \"cassandra/connection.py\", line 951, in cassandra.connection.Connection._connect_socket\n",
            "ConnectionRefusedError: [Errno 111] Tried connecting to [('127.0.0.1', 9042)]. Last error: Connection refused\n",
            "ERROR:cassandra.cluster:Control connection failed to connect, shutting down Cluster:\n",
            "Traceback (most recent call last):\n",
            "  File \"cassandra/cluster.py\", line 1740, in cassandra.cluster.Cluster.connect\n",
            "  File \"cassandra/cluster.py\", line 3543, in cassandra.cluster.ControlConnection.connect\n",
            "  File \"cassandra/cluster.py\", line 3588, in cassandra.cluster.ControlConnection._reconnect_internal\n",
            "cassandra.cluster.NoHostAvailable: ('Unable to connect to any servers', {'127.0.0.1:9042': ConnectionRefusedError(111, \"Tried connecting to [('127.0.0.1', 9042)]. Last error: Connection refused\")})\n"
          ]
        },
        {
          "output_type": "error",
          "ename": "NoHostAvailable",
          "evalue": "('Unable to connect to any servers', {'127.0.0.1:9042': ConnectionRefusedError(111, \"Tried connecting to [('127.0.0.1', 9042)]. Last error: Connection refused\")})",
          "traceback": [
            "\u001b[0;31m---------------------------------------------------------------------------\u001b[0m",
            "\u001b[0;31mNoHostAvailable\u001b[0m                           Traceback (most recent call last)",
            "\u001b[0;32m<ipython-input-6-0fd24203993a>\u001b[0m in \u001b[0;36m<cell line: 2>\u001b[0;34m()\u001b[0m\n\u001b[1;32m      1\u001b[0m \u001b[0mcluster\u001b[0m \u001b[0;34m=\u001b[0m \u001b[0mCluster\u001b[0m\u001b[0;34m(\u001b[0m\u001b[0mprotocol_version\u001b[0m \u001b[0;34m=\u001b[0m \u001b[0;36m3\u001b[0m\u001b[0;34m)\u001b[0m\u001b[0;34m\u001b[0m\u001b[0;34m\u001b[0m\u001b[0m\n\u001b[0;32m----> 2\u001b[0;31m \u001b[0msession\u001b[0m \u001b[0;34m=\u001b[0m \u001b[0mcluster\u001b[0m\u001b[0;34m.\u001b[0m\u001b[0mconnect\u001b[0m\u001b[0;34m(\u001b[0m\u001b[0;34m'killrvideo'\u001b[0m\u001b[0;34m)\u001b[0m\u001b[0;34m\u001b[0m\u001b[0;34m\u001b[0m\u001b[0m\n\u001b[0m",
            "\u001b[0;32m/usr/local/lib/python3.10/dist-packages/cassandra/cluster.cpython-310-x86_64-linux-gnu.so\u001b[0m in \u001b[0;36mcassandra.cluster.Cluster.connect\u001b[0;34m()\u001b[0m\n",
            "\u001b[0;32m/usr/local/lib/python3.10/dist-packages/cassandra/cluster.cpython-310-x86_64-linux-gnu.so\u001b[0m in \u001b[0;36mcassandra.cluster.Cluster.connect\u001b[0;34m()\u001b[0m\n",
            "\u001b[0;32m/usr/local/lib/python3.10/dist-packages/cassandra/cluster.cpython-310-x86_64-linux-gnu.so\u001b[0m in \u001b[0;36mcassandra.cluster.Cluster.connect\u001b[0;34m()\u001b[0m\n",
            "\u001b[0;32m/usr/local/lib/python3.10/dist-packages/cassandra/cluster.cpython-310-x86_64-linux-gnu.so\u001b[0m in \u001b[0;36mcassandra.cluster.ControlConnection.connect\u001b[0;34m()\u001b[0m\n",
            "\u001b[0;32m/usr/local/lib/python3.10/dist-packages/cassandra/cluster.cpython-310-x86_64-linux-gnu.so\u001b[0m in \u001b[0;36mcassandra.cluster.ControlConnection._reconnect_internal\u001b[0;34m()\u001b[0m\n",
            "\u001b[0;31mNoHostAvailable\u001b[0m: ('Unable to connect to any servers', {'127.0.0.1:9042': ConnectionRefusedError(111, \"Tried connecting to [('127.0.0.1', 9042)]. Last error: Connection refused\")})"
          ]
        }
      ]
    }
  ]
}